Workbook

Sheet Май 26
A1: Дата | B1: Ответственный | C1: Клиент | D1: Статус обращения | E1: Срок решения и комментарий | F1: Решение (ссылка на тикет/ссылка на документацию) | G1: Обращение клиента | H1: Время | I1: Статус внесения обращения в Obsidian | J1: Ссылка на Merge Request
A2: 46143 | B2: Мишина Анна | H2: 9:00-10:00
B3: Мишина Анна | H3: 10:00-11:00
B4: Мишина Анна | H4: 11:00-12:00
B5: Мишина Анна | H5: 12:00-13:00
B6: Мишина Анна | H6: 13:00-14:00
B7: Мишина Анна | H7: 14:00-15:00
B8: Мишина Анна | H8: 15:00-16:00
B9: Мишина Анна | H9: 16:00-17:00
B10: Мишина Анна | H10: 17:00-18:00
B11: Мишина Анна | H11: 18:00-19:00
B12: Мишина Анна | H12: 19:00-20:00
B13: Мишина Анна | H13: 20:00-21:00
B14: Мишина Анна | H14: 21:00-22:00
B15: Мишина Анна | H15: 22:00-23:00
A16: 46144 | B16: Мишина Анна | H16: 9:00-10:00
B17: Мишина Анна | H17: 10:00-11:00
B18: Мишина Анна | H18: 11:00-12:00
B19: Мишина Анна | H19: 12:00-13:00
B20: Мишина Анна | H20: 13:00-14:00
B21: Мишина Анна | H21: 14:00-15:00
B22: Мишина Анна | H22: 15:00-16:00
B23: Мишина Анна | H23: 16:00-17:00
B24: Мишина Анна | H24: 17:00-18:00
B25: Мишина Анна | H25: 18:00-19:00
B26: Мишина Анна | H26: 19:00-20:00
B27: Мишина Анна | H27: 20:00-21:00
B28: Мишина Анна | H28: 21:00-22:00
B29: Мишина Анна | H29: 22:00-23:00
A30: 46145 | B30: Мишина Анна | H30: 9:00-10:00
B31: Мишина Анна | H31: 10:00-11:00
B32: Мишина Анна | H32: 11:00-12:00
B33: Мишина Анна | H33: 12:00-13:00
B34: Мишина Анна | H34: 13:00-14:00
B35: Мишина Анна | H35: 14:00-15:00
B36: Мишина Анна | H36: 15:00-16:00
B37: Мишина Анна | H37: 16:00-17:00
B38: Мишина Анна | H38: 17:00-18:00
B39: Мишина Анна | H39: 18:00-19:00
B40: Мишина Анна | H40: 19:00-20:00
...

Sheet Информация
A2: Статус по занятости членов команды для поиска замены
A3: смогу
A4: возможно смогу
A5: не смогу
A8: Клиент | B8: Количество обращений

Sheet ТИКЕТЫ В РАБОТЕ
A1: =IFERROR(__xludf.DUMMYFUNCTION("QUERY({ 'Июль 25'!A:H; 'Июнь 25'!A:H; 'Май 25'!A:H; 'Апрель 25'!A:H; 'Март 25'!A:H; 'Февраль 25'!A:H; 'Январь 25'!A:H; 'Декабрь 24'!A:H; 'Ноябрь 24'!A:H; 'Октябрь 24'!A:H; 'Сентябрь 24'!A:H; 'Июнь 24'!A:H; 'Июль 24'!A:H; 'Авгус"&"т 24'!A:H; 'Май 24'!A:H; 'Апрель 24'!A:H; 'Март 24'!A:H }, ""select Col1, Col2, Col3, Col4, Col5, Col6, Col7, Col8 where Col4 = 'Создан тикет' OR Col4 = 'В работе'"", 1)"),"") | B1: =IFERROR(__xludf.DUMMYFUNCTION("""COMPUTED_VALUE"""),"Ответственный") -> Ответственный | C1: =IFERROR(__xludf.DUMMYFUNCTION("""COMPUTED_VALUE"""),"Клиент") -> Клиент | D1: =IFERROR(__xludf.DUMMYFUNCTION("""COMPUTED_VALUE"""),"Статус обращения") -> Статус обращения | E1: =IFERROR(__xludf.DUMMYFUNCTION("""COMPUTED_VALUE"""),"Срок решения и комментарий") -> Срок решения и комментарий | F1: =IFERROR(__xludf.DUMMYFUNCTION("""COMPUTED_VALUE"""),"Решение (ссылка на тикет/ссылка на документацию)") -> Решение (ссылка на тикет/ссылка на документацию) | G1: =IFERROR(__xludf.DUMMYFUNCTION("""COMPUTED_VALUE"""),"Обращение клиента") -> Обращение клиента | H1: =IFERROR(__xludf.DUMMYFUNCTION("""COMPUTED_VALUE"""),"Время") -> Время
B2: =IFERROR(__xludf.DUMMYFUNCTION("""COMPUTED_VALUE"""),"Червякова Ольга") -> Червякова Ольга | C2: =IFERROR(__xludf.DUMMYFUNCTION("""COMPUTED_VALUE"""),"КХЛ") -> КХЛ | D2: =IFERROR(__xludf.DUMMYFUNCTION("""COMPUTED_VALUE"""),"Создан тикет") -> Создан тикет | G2: =IFERROR(__xludf.DUMMYFUNCTION("""COMPUTED_VALUE"""),"Коллеги, заметил один момент на вебкастере. Через поиск хочу найти все голы Виноградова за сезон 24/25") -> Коллеги, заметил один момент на вебкастере. Через поиск хочу найти все голы Виноградова за сезон 24/25 | H2: =IFERROR(__xludf.DUMMYFUNCTION("""COMPUTED_VALUE"""),"13:00-14:00") -> 13:00-14:00
B3: =IFERROR(__xludf.DUMMYFUNCTION("""COMPUTED_VALUE"""),"Червякова Ольга") -> Червякова Ольга | C3: =IFERROR(__xludf.DUMMYFUNCTION("""COMPUTED_VALUE"""),"RDS") -> RDS | D3: =IFERROR(__xludf.DUMMYFUNCTION("""COMPUTED_VALUE"""),"В работе") -> В работе | G3: =IFERROR(__xludf.DUMMYFUNCTION("""COMPUTED_VALUE"""),"Коллеги, добрый день! Посмотрите, пожалуйста, запрос от пользователя: Плеер нормально работает только в режиме окна, а в полноэкранном режиме картинка дёргается так, что невозможно смотреть. Подскажите, что можно ответить?") -> Коллеги, добрый день! Посмотрите, пожалуйста, запрос от пользователя: Плеер нормально работает только в режиме окна, а в полноэкранном режиме картинка дёргается так, что невозможно смотреть. Подскажите, что можно ответить? | H3: =IFERROR(__xludf.DUMMYFUNCTION("""COMPUTED_VALUE"""),"16:00-17:00") -> 16:00-17:00
B4: =IFERROR(__xludf.DUMMYFUNCTION("""COMPUTED_VALUE"""),"Червякова Ольга") -> Червякова Ольга | C4: =IFERROR(__xludf.DUMMYFUNCTION("""COMPUTED_VALUE"""),"МатчТВ") -> МатчТВ | D4: =IFERROR(__xludf.DUMMYFUNCTION("""COMPUTED_VALUE"""),"В работе") -> В работе | G4: =IFERROR(__xludf.DUMMYFUNCTION("""COMPUTED_VALUE"""),"Здравствуйте. Коллеги, проблема с загрузкой файла по ссылке. Загружаю: https://fc.gpm-match.ru/index.php/s/PEF86rCfTb5Qyw4 Получаю результат: https://video.matchtv.ru/client/events/1279141") -> Здравствуйте. Коллеги, проблема с загрузкой файла по ссылке. Загружаю: https://fc.gpm-match.ru/index.php/s/PEF86rCfTb5Qyw4 Получаю результат: https://video.matchtv.ru/client/events/1279141 | H4: =IFERROR(__xludf.DUMMYFUNCTION("""COMPUTED_VALUE"""),"18:00-19:00") -> 18:00-19:00
B5: =IFERROR(__xludf.DUMMYFUNCTION("""COMPUTED_VALUE"""),"Червякова Ольга") -> Червякова Ольга | C5: =IFERROR(__xludf.DUMMYFUNCTION("""COMPUTED_VALUE"""),"МатчТВ") -> МатчТВ | D5: =IFERROR(__xludf.DUMMYFUNCTION("""COMPUTED_VALUE"""),"В работе") -> В работе | G5: =IFERROR(__xludf.DUMMYFUNCTION("""COMPUTED_VALUE"""),"Добрый день. Установка «заглушки» на дополнительные камеры РПЛ, сломало отображение доп. камер - бесконечное ожидание вместо «заглушки».") -> Добрый день. Установка «заглушки» на дополнительные камеры РПЛ, сломало отображение доп. камер - бесконечное ожидание вместо «заглушки». | H5: =IFERROR(__xludf.DUMMYFUNCTION("""COMPUTED_VALUE"""),"16:00-17:00") -> 16:00-17:00
B6: =IFERROR(__xludf.DUMMYFUNCTION("""COMPUTED_VALUE"""),"Толкачев Егор") -> Толкачев Егор | C6: =IFERROR(__xludf.DUMMYFUNCTION("""COMPUTED_VALUE"""),"Restream") -> Restream | D6: =IFERROR(__xludf.DUMMYFUNCTION("""COMPUTED_VALUE"""),"В работе") -> В работе | G6: =IFERROR(__xludf.DUMMYFUNCTION("""COMPUTED_VALUE"""),"Здравствуйте, продолжает скакать картинка") -> Здравствуйте, продолжает скакать картинка | H6: =IFERROR(__xludf.DUMMYFUNCTION("""COMPUTED_VALUE"""),"19:00-20:00") -> 19:00-20:00
B7: =IFERROR(__xludf.DUMMYFUNCTION("""COMPUTED_VALUE"""),"Алексеева Александра") -> Алексеева Александра | C7: =IFERROR(__xludf.DUMMYFUNCTION("""COMPUTED_VALUE"""),"ТВСтарт") -> ТВСтарт | D7: =IFERROR(__xludf.DUMMYFUNCTION("""COMPUTED_VALUE"""),"Создан тикет") -> Создан тикет | F7: =IFERROR(__xludf.DUMMYFUNCTION("""COMPUTED_VALUE"""),"https://rdm.inventos.ru/issues/159051") -> https://rdm.inventos.ru/issues/159051 | G7: =IFERROR(__xludf.DUMMYFUNCTION("""COMPUTED_VALUE"""),"Добрый день. Как там наш сервер поживает, скоро запустим?") -> Добрый день. Как там наш сервер поживает, скоро запустим? | H7: =IFERROR(__xludf.DUMMYFUNCTION("""COMPUTED_VALUE"""),"12:00-13:00") -> 12:00-13:00
B8: =IFERROR(__xludf.DUMMYFUNCTION("""COMPUTED_VALUE"""),"Алексеева Александра") -> Алексеева Александра | C8: =IFERROR(__xludf.DUMMYFUNCTION("""COMPUTED_VALUE"""),"ЛигаВТБ") -> ЛигаВТБ | D8: =IFERROR(__xludf.DUMMYFUNCTION("""COMPUTED_VALUE"""),"Создан тикет") -> Создан тикет | F8: =IFERROR(__xludf.DUMMYFUNCTION("""COMPUTED_VALUE"""),"https://rdm.inventos.ru/issues/160903") -> https://rdm.inventos.ru/issues/160903 | G8: =IFERROR(__xludf.DUMMYFUNCTION("""COMPUTED_VALUE"""),"Виталий Брагин, [10 июня 2025 г., 10:52:26]: Здравствуйте. Давайте отключим совсем сервер ВТБ SDI 5,6,7,8 эти каналы мы переведём на новый сервер, они нам не понадобятся летом. Хотя нет. эти каналы разбросаны по разным серверам. Лучше отключим сервер 1,"&"2,3,4 совсем и переместим каналы на новый сервер. Сервер мы получается возвращаем вам.") -> Виталий Брагин, [10 июня 2025 г., 10:52:26]: Здравствуйте. Давайте отключим совсем сервер ВТБ SDI 5,6,7,8 эти каналы мы переведём на новый сервер, они нам не понадобятся летом. Хотя нет. эти каналы разбросаны по разным серверам. Лучше отключим сервер 1,2,3,4 совсем и переместим каналы на новый сервер. Сервер мы получается возвращаем вам. | H8: =IFERROR(__xludf.DUMMYFUNCTION("""COMPUTED_VALUE"""),"10:00-11:00") -> 10:00-11:00
B9: =IFERROR(__xludf.DUMMYFUNCTION("""COMPUTED_VALUE"""),"Толкачев Егор") -> Толкачев Егор | C9: =IFERROR(__xludf.DUMMYFUNCTION("""COMPUTED_VALUE"""),"Restream") -> Restream | D9: =IFERROR(__xludf.DUMMYFUNCTION("""COMPUTED_VALUE"""),"Создан тикет") -> Создан тикет | F9: =IFERROR(__xludf.DUMMYFUNCTION("""COMPUTED_VALUE"""),"https://rdm.inventos.ru/issues/161135") -> https://rdm.inventos.ru/issues/161135 | G9: =IFERROR(__xludf.DUMMYFUNCTION("""COMPUTED_VALUE"""),"Добрый вечер! Почему то вчера и сегодня в вечернее время трансляция приходит на restream, но в ВК вобще не пошла а на Ютюб пошла минут через 8 после начала эфира") -> Добрый вечер! Почему то вчера и сегодня в вечернее время трансляция приходит на restream, но в ВК вобще не пошла а на Ютюб пошла минут через 8 после начала эфира | H9: =IFERROR(__xludf.DUMMYFUNCTION("""COMPUTED_VALUE"""),"20:00-21:00") -> 20:00-21:00
B10: =IFERROR(__xludf.DUMMYFUNCTION("""COMPUTED_VALUE"""),"Алексеева Александра") -> Алексеева Александра | C10: =IFERROR(__xludf.DUMMYFUNCTION("""COMPUTED_VALUE"""),"ЛигаВТБ") -> ЛигаВТБ | D10: =IFERROR(__xludf.DUMMYFUNCTION("""COMPUTED_VALUE"""),"Создан тикет") -> Создан тикет | E10: =IFERROR(__xludf.DUMMYFUNCTION("""COMPUTED_VALUE"""),"Костя ответил") -> Костя ответил | F10: =IFERROR(__xludf.DUMMYFUNCTION("""COMPUTED_VALUE"""),"https://rdm.inventos.ru/issues/160903") -> https://rdm.inventos.ru/issues/160903 | G10: =IFERROR(__xludf.DUMMYFUNCTION("""COMPUTED_VALUE"""),"Здравствуйте. Подскажите, как проходит процесс переноса данный с сервера ВТБ ?") -> Здравствуйте. Подскажите, как проходит процесс переноса данный с сервера ВТБ ? | H10: =IFERROR(__xludf.DUMMYFUNCTION("""COMPUTED_VALUE"""),"13:00-14:00") -> 13:00-14:00
B11: =IFERROR(__xludf.DUMMYFUNCTION("""COMPUTED_VALUE"""),"Алексеева Александра") -> Алексеева Александра | C11: =IFERROR(__xludf.DUMMYFUNCTION("""COMPUTED_VALUE"""),"МатчТВ") -> МатчТВ | D11: =IFERROR(__xludf.DUMMYFUNCTION("""COMPUTED_VALUE"""),"Создан тикет") -> Создан тикет | F11: =IFERROR(__xludf.DUMMYFUNCTION("""COMPUTED_VALUE"""),"https://rdm.inventos.ru/issues/161279") -> https://rdm.inventos.ru/issues/161279 | G11: =IFERROR(__xludf.DUMMYFUNCTION("""COMPUTED_VALUE"""),"Доброе утро! @small9rose помогите, пожалуйста, разобраться с пользователем. UID LNrTyVjmWnugex5DCELcMX https://api.video.matchtv.ru/client/users/2352501 Перехожу в транзакции, а там у данного пользователя почему то множество покупок и разные почты. Реа"&"льная покупка пользователя 23 июня 2025 в 10:25 https://api.video.matchtv.ru/admin/transactions?date_from=2024-08-31&transaction%5Bcustomer%5D=2352501") -> Доброе утро! @small9rose помогите, пожалуйста, разобраться с пользователем. UID LNrTyVjmWnugex5DCELcMX https://api.video.matchtv.ru/client/users/2352501 Перехожу в транзакции, а там у данного пользователя почему то множество покупок и разные почты. Реальная покупка пользователя 23 июня 2025 в 10:25 https://api.video.matchtv.ru/admin/transactions?date_from=2024-08-31&transaction%5Bcustomer%5D=2352501 | H11: =IFERROR(__xludf.DUMMYFUNCTION("""COMPUTED_VALUE"""),"10:00-11:00") -> 10:00-11:00
B12: =IFERROR(__xludf.DUMMYFUNCTION("""COMPUTED_VALUE"""),"Алексеева Александра") -> Алексеева Александра | C12: =IFERROR(__xludf.DUMMYFUNCTION("""COMPUTED_VALUE"""),"МатчТВ") -> МатчТВ | D12: =IFERROR(__xludf.DUMMYFUNCTION("""COMPUTED_VALUE"""),"Создан тикет") -> Создан тикет | F12: =IFERROR(__xludf.DUMMYFUNCTION("""COMPUTED_VALUE"""),"https://rdm.inventos.ru/issues/161291") -> https://rdm.inventos.ru/issues/161291 | G12: =IFERROR(__xludf.DUMMYFUNCTION("""COMPUTED_VALUE"""),"@konyshevvvv @small9rose добрый день! Мы закончили снимать с публикации ролики и трансляции немецких футбольных турниров, на которые у нас истекли права. Можно начать очищать от них хранилище: Удалить все ролики и трансляции: У которых есть признак ""Т"&"урнир"": - Бундеслига (Германия); - Кубок Германии 2024-25; - Суперкубок Германии. 2024; - Суперкубок Германии. 2023; - Вторая Бундеслига 2024-25; - Вторая Бундеслига (Германия). У которых в поле ""Название"" есть сочетания: - Чемпионат Германии; - Чемп"&"ионата Германии; - Кубок Германии; - Кубка Германии; - Суперкубок Германии; - Суперкубка Германии; - Вторая Бундеслига; - Второй Бундеслиги.") -> @konyshevvvv @small9rose добрый день! Мы закончили снимать с публикации ролики и трансляции немецких футбольных турниров, на которые у нас истекли права. Можно начать очищать от них хранилище: Удалить все ролики и трансляции: У которых есть признак "Турнир": - Бундеслига (Германия); - Кубок Германии 2024-25; - Суперкубок Германии. 2024; - Суперкубок Германии. 2023; - Вторая Бундеслига 2024-25; - Вторая Бундеслига (Германия). У которых в поле "Название" есть сочетания: - Чемпионат Германии; - Чемпионата Германии; - Кубок Германии; - Кубка Германии; - Суперкубок Германии; - Суперкубка Германии; - Вторая Бундеслига; - Второй Бундеслиги. | H12: =IFERROR(__xludf.DUMMYFUNCTION("""COMPUTED_VALUE"""),"12:00-13:00") -> 12:00-13:00
B13: =IFERROR(__xludf.DUMMYFUNCTION("""COMPUTED_VALUE"""),"Толкачев Егор") -> Толкачев Егор | C13: =IFERROR(__xludf.DUMMYFUNCTION("""COMPUTED_VALUE"""),"Restream") -> Restream | D13: =IFERROR(__xludf.DUMMYFUNCTION("""COMPUTED_VALUE"""),"В работе") -> В работе | G13: =IFERROR(__xludf.DUMMYFUNCTION("""COMPUTED_VALUE"""),"Хочу сделать рестрим с тик тока. Скачал тик ток студию , но он не дает запускать, пишет что 180 дней не было эфира, как это исправить ?") -> Хочу сделать рестрим с тик тока. Скачал тик ток студию , но он не дает запускать, пишет что 180 дней не было эфира, как это исправить ? | H13: =IFERROR(__xludf.DUMMYFUNCTION("""COMPUTED_VALUE"""),"15:00-16:00") -> 15:00-16:00
B14: =IFERROR(__xludf.DUMMYFUNCTION("""COMPUTED_VALUE"""),"Щемелинин Владислав ") -> Щемелинин Владислав | C14: =IFERROR(__xludf.DUMMYFUNCTION("""COMPUTED_VALUE"""),"Restream") -> Restream | D14: =IFERROR(__xludf.DUMMYFUNCTION("""COMPUTED_VALUE"""),"Создан тикет") -> Создан тикет | E14: =IFERROR(__xludf.DUMMYFUNCTION("""COMPUTED_VALUE"""),"Передал Сегегину для решения") -> Передал Сегегину для решения | F14: =IFERROR(__xludf.DUMMYFUNCTION("""COMPUTED_VALUE"""),"https://rdm.inventos.ru/issues/160551") -> https://rdm.inventos.ru/issues/160551 | G14: =IFERROR(__xludf.DUMMYFUNCTION("""COMPUTED_VALUE"""),"Дергается картинка на стриме") -> Дергается картинка на стриме | H14: =IFERROR(__xludf.DUMMYFUNCTION("""COMPUTED_VALUE"""),"20:00-21:00") -> 20:00-21:00
A15: =IFERROR(__xludf.DUMMYFUNCTION("""COMPUTED_VALUE"""),45750) -> 45750 | B15: =IFERROR(__xludf.DUMMYFUNCTION("""COMPUTED_VALUE"""),"Алексеева Александра") -> Алексеева Александра | C15: =IFERROR(__xludf.DUMMYFUNCTION("""COMPUTED_VALUE"""),"Restream") -> Restream | D15: =IFERROR(__xludf.DUMMYFUNCTION("""COMPUTED_VALUE"""),"Создан тикет") -> Создан тикет | F15: =IFERROR(__xludf.DUMMYFUNCTION("""COMPUTED_VALUE"""),"https://rdm.inventos.ru/issues/156599") -> https://rdm.inventos.ru/issues/156599 | G15: =IFERROR(__xludf.DUMMYFUNCTION("""COMPUTED_VALUE"""),"ребята, привет. я все понимаю, но уже полмесяца чат толком не работает на стримах. можно все-таки узнать, когда будет обновление, которое эту проблему уже решит? трансляции проводить в таких условиях не комфортно ни нам, ни зрителям.") -> ребята, привет. я все понимаю, но уже полмесяца чат толком не работает на стримах. можно все-таки узнать, когда будет обновление, которое эту проблему уже решит? трансляции проводить в таких условиях не комфортно ни нам, ни зрителям. | H15: =IFERROR(__xludf.DUMMYFUNCTION("""COMPUTED_VALUE"""),"9:00-10:00") -> 9:00-10:00
A16: =IFERROR(__xludf.DUMMYFUNCTION("""COMPUTED_VALUE"""),45738) -> 45738 | B16: =IFERROR(__xludf.DUMMYFUNCTION("""COMPUTED_VALUE"""),"Алексеева Александра") -> Алексеева Александра | C16: =IFERROR(__xludf.DUMMYFUNCTION("""COMPUTED_VALUE"""),"Restream") -> Restream | D16: =IFERROR(__xludf.DUMMYFUNCTION("""COMPUTED_VALUE"""),"Создан тикет") -> Создан тикет | F16: =IFERROR(__xludf.DUMMYFUNCTION("""COMPUTED_VALUE"""),"https://rdm.inventos.ru/issues/156599 ") -> https://rdm.inventos.ru/issues/156599 | G16: =IFERROR(__xludf.DUMMYFUNCTION("""COMPUTED_VALUE"""),"Здравствуйте. Чат по-прежнему не собирает в себя сообщения самостоятельно. Приходится постоянно вручную обновлять кэш, чтобы сообщения прогружались") -> Здравствуйте. Чат по-прежнему не собирает в себя сообщения самостоятельно. Приходится постоянно вручную обновлять кэш, чтобы сообщения прогружались | H16: =IFERROR(__xludf.DUMMYFUNCTION("""COMPUTED_VALUE"""),"9:00-10:00") -> 9:00-10:00
B17: =IFERROR(__xludf.DUMMYFUNCTION("""COMPUTED_VALUE"""),"Алексеева Александра") -> Алексеева Александра | C17: =IFERROR(__xludf.DUMMYFUNCTION("""COMPUTED_VALUE"""),"Restream") -> Restream | D17: =IFERROR(__xludf.DUMMYFUNCTION("""COMPUTED_VALUE"""),"Создан тикет") -> Создан тикет | F17: =IFERROR(__xludf.DUMMYFUNCTION("""COMPUTED_VALUE"""),"https://rdm.inventos.ru/issues/156599") -> https://rdm.inventos.ru/issues/156599 | G17: =IFERROR(__xludf.DUMMYFUNCTION("""COMPUTED_VALUE"""),"добрый день, столкнулся с такой проблемой: сообщения из чатов не передаются в обс. то есть они попадают в сам чат рестрима, но не передаются на докпанель в обсе. уже перепробовал все возможное - от переустановки обс до чистки кэша и различных перезапусков"&". другие док панели работают корректно, например если выводить в док панель чат с твича. но чат с рестрима не работает ни в какую. может быть можете подсказать, как это можно поправить? возможно у кого уже была такая проблема :(") -> добрый день, столкнулся с такой проблемой: сообщения из чатов не передаются в обс. то есть они попадают в сам чат рестрима, но не передаются на докпанель в обсе. уже перепробовал все возможное - от переустановки обс до чистки кэша и различных перезапусков. другие док панели работают корректно, например если выводить в док панель чат с твича. но чат с рестрима не работает ни в какую. может быть можете подсказать, как это можно поправить? возможно у кого уже была такая проблема :( | H17: =IFERROR(__xludf.DUMMYFUNCTION("""COMPUTED_VALUE"""),"11:00-12:00") -> 11:00-12:00
B18: =IFERROR(__xludf.DUMMYFUNCTION("""COMPUTED_VALUE"""),"Тимохина Дарья ") -> Тимохина Дарья | C18: =IFERROR(__xludf.DUMMYFUNCTION("""COMPUTED_VALUE"""),"ТВСтарт") -> ТВСтарт | D18: =IFERROR(__xludf.DUMMYFUNCTION("""COMPUTED_VALUE"""),"Создан тикет") -> Создан тикет | E18: =IFERROR(__xludf.DUMMYFUNCTION("""COMPUTED_VALUE"""),"https://rdm.inventos.ru/issues/157723") -> https://rdm.inventos.ru/issues/157723 | F18: =IFERROR(__xludf.DUMMYFUNCTION("""COMPUTED_VALUE"""),"Была аналогичная ситуация уже, создала тикет, работы ведутся. ") -> Была аналогичная ситуация уже, создала тикет, работы ведутся. | G18: =IFERROR(__xludf.DUMMYFUNCTION("""COMPUTED_VALUE"""),"Вот ещё возьмите, пожалуйста, такую просьбу в работу? Мы удаляем контент из событий примерно раньше квартала к текущей дате. Сейчас открыл архив событий и в прошлом году все ивенты с неудалённым контентом. Можете посмотреть, разобраться? У нас было такое "&"уже, в списке отображается наличие контента, в ивент заходишь - там пусто.") -> Вот ещё возьмите, пожалуйста, такую просьбу в работу? Мы удаляем контент из событий примерно раньше квартала к текущей дате. Сейчас открыл архив событий и в прошлом году все ивенты с неудалённым контентом. Можете посмотреть, разобраться? У нас было такое уже, в списке отображается наличие контента, в ивент заходишь - там пусто. | H18: =IFERROR(__xludf.DUMMYFUNCTION("""COMPUTED_VALUE"""),"14:00-15:00") -> 14:00-15:00
B19: =IFERROR(__xludf.DUMMYFUNCTION("""COMPUTED_VALUE"""),"Червякова Ольга") -> Червякова Ольга | C19: =IFERROR(__xludf.DUMMYFUNCTION("""COMPUTED_VALUE"""),"Restream") -> Restream | D19: =IFERROR(__xludf.DUMMYFUNCTION("""COMPUTED_VALUE"""),"В работе") -> В работе | E19: =IFERROR(__xludf.DUMMYFUNCTION("""COMPUTED_VALUE"""),"тикет на тестировании") -> тикет на тестировании | G19: =IFERROR(__xludf.DUMMYFUNCTION("""COMPUTED_VALUE"""),"Ребята, привет. У нас стрим опять начал пропускать сообщения с вк и твича") -> Ребята, привет. У нас стрим опять начал пропускать сообщения с вк и твича | H19: =IFERROR(__xludf.DUMMYFUNCTION("""COMPUTED_VALUE"""),"20:00-21:00") -> 20:00-21:00
B20: =IFERROR(__xludf.DUMMYFUNCTION("""COMPUTED_VALUE"""),"Алексеева Александра") -> Алексеева Александра | C20: =IFERROR(__xludf.DUMMYFUNCTION("""COMPUTED_VALUE"""),"МОНИКИ") -> МОНИКИ | D20: =IFERROR(__xludf.DUMMYFUNCTION("""COMPUTED_VALUE"""),"Создан тикет") -> Создан тикет | F20: =IFERROR(__xludf.DUMMYFUNCTION("""COMPUTED_VALUE"""),"https://rdm.inventos.ru/issues/157875") -> https://rdm.inventos.ru/issues/157875 | G20: =IFERROR(__xludf.DUMMYFUNCTION("""COMPUTED_VALUE""")," Доброе утро коллеги! https://wbnr.su:50443/rooms?meet=cf81c5e8-4966-44f0-85ea-f02769477297 посмотрите лекцию подалуйста никто не может зайти") -> Доброе утро коллеги! https://wbnr.su:50443/rooms?meet=cf81c5e8-4966-44f0-85ea-f02769477297 посмотрите лекцию подалуйста никто не может зайти | H20: =IFERROR(__xludf.DUMMYFUNCTION("""COMPUTED_VALUE"""),"10:00-11:00") -> 10:00-11:00
B21: =IFERROR(__xludf.DUMMYFUNCTION("""COMPUTED_VALUE"""),"Алексеева Александра") -> Алексеева Александра | C21: =IFERROR(__xludf.DUMMYFUNCTION("""COMPUTED_VALUE"""),"МОНИКИ") -> МОНИКИ | D21: =IFERROR(__xludf.DUMMYFUNCTION("""COMPUTED_VALUE"""),"Создан тикет") -> Создан тикет | F21: =IFERROR(__xludf.DUMMYFUNCTION("""COMPUTED_VALUE"""),"https://rdm.inventos.ru/issues/157875") -> https://rdm.inventos.ru/issues/157875 | G21: =IFERROR(__xludf.DUMMYFUNCTION("""COMPUTED_VALUE"""),"Коллеги, лектора выкидывает с вебинара") -> Коллеги, лектора выкидывает с вебинара | H21: =IFERROR(__xludf.DUMMYFUNCTION("""COMPUTED_VALUE"""),"10:00-11:00") -> 10:00-11:00
B22: =IFERROR(__xludf.DUMMYFUNCTION("""COMPUTED_VALUE"""),"Алексеева Александра") -> Алексеева Александра | C22: =IFERROR(__xludf.DUMMYFUNCTION("""COMPUTED_VALUE"""),"МОНИКИ") -> МОНИКИ | D22: =IFERROR(__xludf.DUMMYFUNCTION("""COMPUTED_VALUE"""),"Создан тикет") -> Создан тикет | F22: =IFERROR(__xludf.DUMMYFUNCTION("""COMPUTED_VALUE"""),"https://rdm.inventos.ru/issues/157875") -> https://rdm.inventos.ru/issues/157875 | G22: =IFERROR(__xludf.DUMMYFUNCTION("""COMPUTED_VALUE"""),"Доброе утро! История повторилась вчерашняя") -> Доброе утро! История повторилась вчерашняя | H22: =IFERROR(__xludf.DUMMYFUNCTION("""COMPUTED_VALUE"""),"10:00-11:00") -> 10:00-11:00
A23: =IFERROR(__xludf.DUMMYFUNCTION("""COMPUTED_VALUE"""),45714) -> 45714 | B23: =IFERROR(__xludf.DUMMYFUNCTION("""COMPUTED_VALUE"""),"Алексеева Александра") -> Алексеева Александра | C23: =IFERROR(__xludf.DUMMYFUNCTION("""COMPUTED_VALUE"""),"МатчТВ") -> МатчТВ | D23: =IFERROR(__xludf.DUMMYFUNCTION("""COMPUTED_VALUE"""),"Создан тикет") -> Создан тикет | E23: =IFERROR(__xludf.DUMMYFUNCTION("""COMPUTED_VALUE"""),"https://rdm.inventos.ru/issues/157987") -> https://rdm.inventos.ru/issues/157987 | F23: =IFERROR(__xludf.DUMMYFUNCTION("""COMPUTED_VALUE"""),"https://mm.inventos.ru/inventos/pl/at4z7asgdbdk3kni7yfs6shhkw") -> https://mm.inventos.ru/inventos/pl/at4z7asgdbdk3kni7yfs6shhkw | G23: =IFERROR(__xludf.DUMMYFUNCTION("""COMPUTED_VALUE"""),"https://news.sportbox.ru/Vidy_sporta/Futbol/Evropejskie_chempionaty/Germaniya/Kubok_Germanii/spbvideo_NI2173002_clip_Arminija___Verder_Goly_video_Kubok_Germanii_Futbol Слишком долго осуществляется склейка и еще наблюдаются торможения в работе админки "&"в целом") -> https://news.sportbox.ru/Vidy_sporta/Futbol/Evropejskie_chempionaty/Germaniya/Kubok_Germanii/spbvideo_NI2173002_clip_Arminija___Verder_Goly_video_Kubok_Germanii_Futbol Слишком долго осуществляется склейка и еще наблюдаются торможения в работе админки в целом | H23: =IFERROR(__xludf.DUMMYFUNCTION("""COMPUTED_VALUE"""),"9:00-10:00") -> 9:00-10:00
B24: =IFERROR(__xludf.DUMMYFUNCTION("""COMPUTED_VALUE"""),"Алексеева Александра") -> Алексеева Александра | C24: =IFERROR(__xludf.DUMMYFUNCTION("""COMPUTED_VALUE"""),"Restream") -> Restream | D24: =IFERROR(__xludf.DUMMYFUNCTION("""COMPUTED_VALUE"""),"Создан тикет") -> Создан тикет | F24: =IFERROR(__xludf.DUMMYFUNCTION("""COMPUTED_VALUE"""),"https://rdm.inventos.ru/issues/156883 https://rdm.inventos.ru/issues/156587 https://rdm.inventos.ru/issues/156955") -> https://rdm.inventos.ru/issues/156883 https://rdm.inventos.ru/issues/156587 https://rdm.inventos.ru/issues/156955 | G24: =IFERROR(__xludf.DUMMYFUNCTION("""COMPUTED_VALUE"""),"Ошибка при авторизации на ютуб") -> Ошибка при авторизации на ютуб | H24: =IFERROR(__xludf.DUMMYFUNCTION("""COMPUTED_VALUE"""),"12:00-13:00") -> 12:00-13:00
B25: =IFERROR(__xludf.DUMMYFUNCTION("""COMPUTED_VALUE"""),"Алексеева Александра") -> Алексеева Александра | C25: =IFERROR(__xludf.DUMMYFUNCTION("""COMPUTED_VALUE"""),"Restream") -> Restream | D25: =IFERROR(__xludf.DUMMYFUNCTION("""COMPUTED_VALUE"""),"Создан тикет") -> Создан тикет | E25: =IFERROR(__xludf.DUMMYFUNCTION("""COMPUTED_VALUE"""),"Пользователь использует нашу платформу в качестве сбора сообщений, при этом пользователь не подае поток на нашу платформу. Благодаря этому случаю удалось найти баг: почему то мультичат собирает сообщения, но при этом на платформу не идет поток и не добавл"&"ены каналы. Этот баг обнаружили вместе с Сашей Серегиным. Ответ пользователю: ""Виджет чата будет работать корректно и собирать все сообщения только при транслировании потока на наш сервис. Если вы будете использовать только виджет, без отправки потока, т"&"о чат не будет работать корректно. Мы рекомендуем вам воспользоваться нашей платформой для рестрима потока на разные платформы.""") -> Пользователь использует нашу платформу в качестве сбора сообщений, при этом пользователь не подае поток на нашу платформу. Благодаря этому случаю удалось найти баг: почему то мультичат собирает сообщения, но при этом на платформу не идет поток и не добавлены каналы. Этот баг обнаружили вместе с Сашей Серегиным. Ответ пользователю: "Виджет чата будет работать корректно и собирать все сообщения только при транслировании потока на наш сервис. Если вы будете использовать только виджет, без отправки потока, то чат не будет работать корректно. Мы рекомендуем вам воспользоваться нашей платформой для рестрима потока на разные платформы." | F25: =IFERROR(__xludf.DUMMYFUNCTION("""COMPUTED_VALUE"""),"https://rdm.inventos.ru/issues/156883. https://rdm.inventos.ru/issues/156587. https://rdm.inventos.ru/issues/156955") -> https://rdm.inventos.ru/issues/156883. https://rdm.inventos.ru/issues/156587. https://rdm.inventos.ru/issues/156955 | G25: =IFERROR(__xludf.DUMMYFUNCTION("""COMPUTED_VALUE"""),"Добрый день.Не работает чат на ютубе, только на твич") -> Добрый день.Не работает чат на ютубе, только на твич | H25: =IFERROR(__xludf.DUMMYFUNCTION("""COMPUTED_VALUE"""),"13:00-14:00") -> 13:00-14:00
B26: =IFERROR(__xludf.DUMMYFUNCTION("""COMPUTED_VALUE"""),"Толкачев Егор") -> Толкачев Егор | C26: =IFERROR(__xludf.DUMMYFUNCTION("""COMPUTED_VALUE"""),"Restream") -> Restream | D26: =IFERROR(__xludf.DUMMYFUNCTION("""COMPUTED_VALUE"""),"В работе") -> В работе | G26: =IFERROR(__xludf.DUMMYFUNCTION("""COMPUTED_VALUE"""),"Ребят, привет. У нас чат сломался щас на стриме. Вообще не собирает сообщения. Я уже кеш сбрасывал. Ничего") -> Ребят, привет. У нас чат сломался щас на стриме. Вообще не собирает сообщения. Я уже кеш сбрасывал. Ничего | H26: =IFERROR(__xludf.DUMMYFUNCTION("""COMPUTED_VALUE"""),"20:00-21:00") -> 20:00-21:00
B27: =IFERROR(__xludf.DUMMYFUNCTION("""COMPUTED_VALUE"""),"Толкачев Егор") -> Толкачев Егор | C27: =IFERROR(__xludf.DUMMYFUNCTION("""COMPUTED_VALUE"""),"Restream") -> Restream | D27: =IFERROR(__xludf.DUMMYFUNCTION("""COMPUTED_VALUE"""),"В работе") -> В работе | G27: =IFERROR(__xludf.DUMMYFUNCTION("""COMPUTED_VALUE"""),"опять с ВК нет комментариев*") -> опять с ВК нет комментариев* | H27: =IFERROR(__xludf.DUMMYFUNCTION("""COMPUTED_VALUE"""),"19:00-20:00") -> 19:00-20:00
B28: =IFERROR(__xludf.DUMMYFUNCTION("""COMPUTED_VALUE"""),"Алексеева Александра") -> Алексеева Александра | C28: =IFERROR(__xludf.DUMMYFUNCTION("""COMPUTED_VALUE"""),"МатчТВ") -> МатчТВ | D28: =IFERROR(__xludf.DUMMYFUNCTION("""COMPUTED_VALUE"""),"Создан тикет") -> Создан тикет | F28: =IFERROR(__xludf.DUMMYFUNCTION("""COMPUTED_VALUE"""),"https://rdm.inventos.ru/issues/156703 https://rdm.inventos.ru/issues/156771 ") -> https://rdm.inventos.ru/issues/156703 https://rdm.inventos.ru/issues/156771 | G28: =IFERROR(__xludf.DUMMYFUNCTION("""COMPUTED_VALUE"""),"Всем привет! На планшетах, проверьте еще, пожалуйста. Возможно связанные проблемы. Получили обращение такое: Так как на айпаде нет официального приложения матч.ТВ, я использую Яндекс браузер. Перестала работать возможность просмотра записей трансляций"&" через этот браузер. Пишет, что трансляция использует функционал, который не поддерживает данный браузер. Пробовал сафари. Итог тот же. Браузер версия 24.12.4 от 2 января 2025 IpadOS 18.1.1 IPad 9го поколения.") -> Всем привет! На планшетах, проверьте еще, пожалуйста. Возможно связанные проблемы. Получили обращение такое: Так как на айпаде нет официального приложения матч.ТВ, я использую Яндекс браузер. Перестала работать возможность просмотра записей трансляций через этот браузер. Пишет, что трансляция использует функционал, который не поддерживает данный браузер. Пробовал сафари. Итог тот же. Браузер версия 24.12.4 от 2 января 2025 IpadOS 18.1.1 IPad 9го поколения. | H28: =IFERROR(__xludf.DUMMYFUNCTION("""COMPUTED_VALUE"""),"10:00-11:00") -> 10:00-11:00
B29: =IFERROR(__xludf.DUMMYFUNCTION("""COMPUTED_VALUE"""),"Червякова Ольга") -> Червякова Ольга | C29: =IFERROR(__xludf.DUMMYFUNCTION("""COMPUTED_VALUE"""),"МатчТВ") -> МатчТВ | D29: =IFERROR(__xludf.DUMMYFUNCTION("""COMPUTED_VALUE"""),"В работе") -> В работе | F29: =IFERROR(__xludf.DUMMYFUNCTION("""COMPUTED_VALUE"""),"Константин проверяет на LG в офисе") -> Константин проверяет на LG в офисе | G29: =IFERROR(__xludf.DUMMYFUNCTION("""COMPUTED_VALUE"""),"Добрый вечер! У пользователя на канале Футбол1, трансляция идет с прерыванием. Другие футбольные каналы работают нормально. Смотрит на смарт тв. IP 194.32.230.128") -> Добрый вечер! У пользователя на канале Футбол1, трансляция идет с прерыванием. Другие футбольные каналы работают нормально. Смотрит на смарт тв. IP 194.32.230.128 | H29: =IFERROR(__xludf.DUMMYFUNCTION("""COMPUTED_VALUE"""),"20:00-21:00") -> 20:00-21:00
B30: =IFERROR(__xludf.DUMMYFUNCTION("""COMPUTED_VALUE"""),"Червякова Ольга") -> Червякова Ольга | C30: =IFERROR(__xludf.DUMMYFUNCTION("""COMPUTED_VALUE"""),"МатчТВ") -> МатчТВ | D30: =IFERROR(__xludf.DUMMYFUNCTION("""COMPUTED_VALUE"""),"В работе") -> В работе | G30: =IFERROR(__xludf.DUMMYFUNCTION("""COMPUTED_VALUE"""),"Добрый день! Пользователю недоступен просмотр канала Матч Премьер на сайте. 30 Jan 25 16:53:40 +0300 GeoIP country: RU GeoIP country nginx: RU GeoIP region nginx: MOW HTTP_USER_AGENT: Mozilla/5.0 (Linux; Android 10; K) AppleWebKit/537.36 (KHTML, like Geck"&"o) Chrome/131.0.6778.260 Mobile Safari/537.36 REMOTE_ADDR: 5.188.121.199 HTTP_X_FORWARDED_FOR: 185.107.136.0 IP-Z: 185.107.136.0 Proxied IP: 5.188.121.199 Network Family: common Current UID/SU: / HAS FLASH: false MSE: true") -> Добрый день! Пользователю недоступен просмотр канала Матч Премьер на сайте. 30 Jan 25 16:53:40 +0300 GeoIP country: RU GeoIP country nginx: RU GeoIP region nginx: MOW HTTP_USER_AGENT: Mozilla/5.0 (Linux; Android 10; K) AppleWebKit/537.36 (KHTML, like Gecko) Chrome/131.0.6778.260 Mobile Safari/537.36 REMOTE_ADDR: 5.188.121.199 HTTP_X_FORWARDED_FOR: 185.107.136.0 IP-Z: 185.107.136.0 Proxied IP: 5.188.121.199 Network Family: common Current UID/SU: / HAS FLASH: false MSE: true | H30: =IFERROR(__xludf.DUMMYFUNCTION("""COMPUTED_VALUE"""),"17:00-18:00") -> 17:00-18:00
B31: =IFERROR(__xludf.DUMMYFUNCTION("""COMPUTED_VALUE"""),"Тимохина Дарья ") -> Тимохина Дарья | C31: =IFERROR(__xludf.DUMMYFUNCTION("""COMPUTED_VALUE"""),"ТВСтарт") -> ТВСтарт | D31: =IFERROR(__xludf.DUMMYFUNCTION("""COMPUTED_VALUE"""),"Создан тикет") -> Создан тикет | G31: =IFERROR(__xludf.DUMMYFUNCTION("""COMPUTED_VALUE"""),"Добрый день! Описываю странное поведение в ЛК Вебкастера. При создании кода внедрения не работает кнопка Копировать, не копируется код в буфер. Она не работает только в типе ембеда Iframe, в других всё ок. Работаю в Опере, кеш чистил.") -> Добрый день! Описываю странное поведение в ЛК Вебкастера. При создании кода внедрения не работает кнопка Копировать, не копируется код в буфер. Она не работает только в типе ембеда Iframe, в других всё ок. Работаю в Опере, кеш чистил. | H31: =IFERROR(__xludf.DUMMYFUNCTION("""COMPUTED_VALUE"""),"15:00-16:00") -> 15:00-16:00
B32: =IFERROR(__xludf.DUMMYFUNCTION("""COMPUTED_VALUE"""),"Григорьев Дмитрий") -> Григорьев Дмитрий | C32: =IFERROR(__xludf.DUMMYFUNCTION("""COMPUTED_VALUE"""),"Restream") -> Restream | D32: =IFERROR(__xludf.DUMMYFUNCTION("""COMPUTED_VALUE"""),"Создан тикет") -> Создан тикет | F32: =IFERROR(__xludf.DUMMYFUNCTION("""COMPUTED_VALUE"""),"https://rdm.inventos.ru/issues/156163") -> https://rdm.inventos.ru/issues/156163 | G32: =IFERROR(__xludf.DUMMYFUNCTION("""COMPUTED_VALUE"""),"Здравствуйте, почему у меня сообщения в чате дублируются, можно исправить?") -> Здравствуйте, почему у меня сообщения в чате дублируются, можно исправить? | H32: =IFERROR(__xludf.DUMMYFUNCTION("""COMPUTED_VALUE"""),"13:00-14:00") -> 13:00-14:00
B33: =IFERROR(__xludf.DUMMYFUNCTION("""COMPUTED_VALUE"""),"Червякова Ольга") -> Червякова Ольга | C33: =IFERROR(__xludf.DUMMYFUNCTION("""COMPUTED_VALUE"""),"ТВСтарт") -> ТВСтарт | D33: =IFERROR(__xludf.DUMMYFUNCTION("""COMPUTED_VALUE"""),"Создан тикет") -> Создан тикет | F33: =IFERROR(__xludf.DUMMYFUNCTION("""COMPUTED_VALUE"""),"https://rdm.inventos.ru/issues/156475") -> https://rdm.inventos.ru/issues/156475 | G33: =IFERROR(__xludf.DUMMYFUNCTION("""COMPUTED_VALUE"""),"Добрый день. Размещаю видео на сервер. И пишет что обработка 130%. Это нормально?") -> Добрый день. Размещаю видео на сервер. И пишет что обработка 130%. Это нормально? | H33: =IFERROR(__xludf.DUMMYFUNCTION("""COMPUTED_VALUE"""),"14:00-15:00") -> 14:00-15:00
B34: =IFERROR(__xludf.DUMMYFUNCTION("""COMPUTED_VALUE"""),"Червякова Ольга") -> Червякова Ольга | C34: =IFERROR(__xludf.DUMMYFUNCTION("""COMPUTED_VALUE"""),"МатчТВ") -> МатчТВ | D34: =IFERROR(__xludf.DUMMYFUNCTION("""COMPUTED_VALUE"""),"Создан тикет") -> Создан тикет | F34: =IFERROR(__xludf.DUMMYFUNCTION("""COMPUTED_VALUE"""),"https://rdm.inventos.ru/issues/155107") -> https://rdm.inventos.ru/issues/155107 | G34: =IFERROR(__xludf.DUMMYFUNCTION("""COMPUTED_VALUE"""),"Добрый день. Коллеги, почему-то не получалось запустить трансляцию из нашей админки. Запускал трансляцию напрямую из вебкастера.") -> Добрый день. Коллеги, почему-то не получалось запустить трансляцию из нашей админки. Запускал трансляцию напрямую из вебкастера. | H34: =IFERROR(__xludf.DUMMYFUNCTION("""COMPUTED_VALUE"""),"15:00-16:00") -> 15:00-16:00
B35: =IFERROR(__xludf.DUMMYFUNCTION("""COMPUTED_VALUE"""),"Алексеева Александра") -> Алексеева Александра | C35: =IFERROR(__xludf.DUMMYFUNCTION("""COMPUTED_VALUE"""),"МатчТВ") -> МатчТВ | D35: =IFERROR(__xludf.DUMMYFUNCTION("""COMPUTED_VALUE"""),"Создан тикет") -> Создан тикет | F35: =IFERROR(__xludf.DUMMYFUNCTION("""COMPUTED_VALUE"""),"https://rdm.inventos.ru/issues/155131") -> https://rdm.inventos.ru/issues/155131 | G35: =IFERROR(__xludf.DUMMYFUNCTION("""COMPUTED_VALUE"""),"Коллеги, добрый день! Иногда сталкиваюсь с проблемой, что при раскрытии веб плеера у меня на какое-то время прогружаются элементы интерфейса плеера, а потом сам плеер. Выглядит странно. Давно эту проблему наблюдаю, но записать удалось только сейчас") -> Коллеги, добрый день! Иногда сталкиваюсь с проблемой, что при раскрытии веб плеера у меня на какое-то время прогружаются элементы интерфейса плеера, а потом сам плеер. Выглядит странно. Давно эту проблему наблюдаю, но записать удалось только сейчас | H35: =IFERROR(__xludf.DUMMYFUNCTION("""COMPUTED_VALUE"""),"11:00-12:00") -> 11:00-12:00
B36: =IFERROR(__xludf.DUMMYFUNCTION("""COMPUTED_VALUE"""),"Червякова Ольга") -> Червякова Ольга | C36: =IFERROR(__xludf.DUMMYFUNCTION("""COMPUTED_VALUE"""),"МатчТВ") -> МатчТВ | D36: =IFERROR(__xludf.DUMMYFUNCTION("""COMPUTED_VALUE"""),"Создан тикет") -> Создан тикет | F36: =IFERROR(__xludf.DUMMYFUNCTION("""COMPUTED_VALUE"""),"https://rdm.inventos.ru/issues/155467") -> https://rdm.inventos.ru/issues/155467 | G36: =IFERROR(__xludf.DUMMYFUNCTION("""COMPUTED_VALUE"""),"Здравствуйте https://news.sportbox.ru/node/2133588 Слишком долго грузится файл по ссылке в ноду уже минут 15 id 1227001") -> Здравствуйте https://news.sportbox.ru/node/2133588 Слишком долго грузится файл по ссылке в ноду уже минут 15 id 1227001 | H36: =IFERROR(__xludf.DUMMYFUNCTION("""COMPUTED_VALUE"""),"22:00-23:00") -> 22:00-23:00
B37: =IFERROR(__xludf.DUMMYFUNCTION("""COMPUTED_VALUE"""),"Тимохина Дарья ") -> Тимохина Дарья | C37: =IFERROR(__xludf.DUMMYFUNCTION("""COMPUTED_VALUE"""),"МатчТВ") -> МатчТВ | D37: =IFERROR(__xludf.DUMMYFUNCTION("""COMPUTED_VALUE"""),"Создан тикет") -> Создан тикет | F37: =IFERROR(__xludf.DUMMYFUNCTION("""COMPUTED_VALUE"""),"https://rdm.inventos.ru/issues/154931") -> https://rdm.inventos.ru/issues/154931 | G37: =IFERROR(__xludf.DUMMYFUNCTION("""COMPUTED_VALUE"""),"На остальных каналах тоже были рассыпания. Сейчас пересматриваем UFC, который был в субботу вечером: https://video.matchtv.ru/client/events/1217337") -> На остальных каналах тоже были рассыпания. Сейчас пересматриваем UFC, который был в субботу вечером: https://video.matchtv.ru/client/events/1217337 | H37: =IFERROR(__xludf.DUMMYFUNCTION("""COMPUTED_VALUE"""),"14:00-15:00") -> 14:00-15:00
B38: =IFERROR(__xludf.DUMMYFUNCTION("""COMPUTED_VALUE"""),"Червякова Ольга") -> Червякова Ольга | C38: =IFERROR(__xludf.DUMMYFUNCTION("""COMPUTED_VALUE"""),"МатчТВ") -> МатчТВ | D38: =IFERROR(__xludf.DUMMYFUNCTION("""COMPUTED_VALUE"""),"Создан тикет") -> Создан тикет | E38: =IFERROR(__xludf.DUMMYFUNCTION("""COMPUTED_VALUE"""),"Баг") -> Баг | G38: =IFERROR(__xludf.DUMMYFUNCTION("""COMPUTED_VALUE"""),"https://rdm.inventos.ru/issues/152223") -> https://rdm.inventos.ru/issues/152223 | H38: =IFERROR(__xludf.DUMMYFUNCTION("""COMPUTED_VALUE"""),"подскажите, пожалуйста, с чем может быть связана разная скорость запуска прямого эфира и разовой трансляции? сейчас, когда мы для подписчиков отключили пре-роллы, заметили, что любая разовая трансляция/обзор/хайлайт запускается моментально, а вот прямой э"&"фир запускается секунды через 4-5, а до этого крутится лоудер") -> подскажите, пожалуйста, с чем может быть связана разная скорость запуска прямого эфира и разовой трансляции? сейчас, когда мы для подписчиков отключили пре-роллы, заметили, что любая разовая трансляция/обзор/хайлайт запускается моментально, а вот прямой эфир запускается секунды через 4-5, а до этого крутится лоудер
B39: =IFERROR(__xludf.DUMMYFUNCTION("""COMPUTED_VALUE"""),"Курасов Павел") -> Курасов Павел | C39: =IFERROR(__xludf.DUMMYFUNCTION("""COMPUTED_VALUE"""),"Ifree") -> Ifree | D39: =IFERROR(__xludf.DUMMYFUNCTION("""COMPUTED_VALUE"""),"Создан тикет") -> Создан тикет | F39: =IFERROR(__xludf.DUMMYFUNCTION("""COMPUTED_VALUE"""),"https://rdm.inventos.ru/issues/152371") -> https://rdm.inventos.ru/issues/152371 | G39: =IFERROR(__xludf.DUMMYFUNCTION("""COMPUTED_VALUE"""),"Добрый день! Можете пожалуйста посмотреть это видео дважды выдало ошибку https://ifree.webcaster.pro/client/video_files/1089827") -> Добрый день! Можете пожалуйста посмотреть это видео дважды выдало ошибку https://ifree.webcaster.pro/client/video_files/1089827 | H39: =IFERROR(__xludf.DUMMYFUNCTION("""COMPUTED_VALUE"""),"10:00-11:00") -> 10:00-11:00
B40: =IFERROR(__xludf.DUMMYFUNCTION("""COMPUTED_VALUE"""),"Червякова Ольга") -> Червякова Ольга | C40: =IFERROR(__xludf.DUMMYFUNCTION("""COMPUTED_VALUE"""),"ТВСтарт") -> ТВСтарт | D40: =IFERROR(__xludf.DUMMYFUNCTION("""COMPUTED_VALUE"""),"Создан тикет") -> Создан тикет | F40: =IFERROR(__xludf.DUMMYFUNCTION("""COMPUTED_VALUE"""),"https://rdm.inventos.ru/issues/153355") -> https://rdm.inventos.ru/issues/153355 | G40: =IFERROR(__xludf.DUMMYFUNCTION("""COMPUTED_VALUE"""),"Ещё вопрос в админке лиги ВТб постоянно выскакивает окно, оно для чего и может его убрать?") -> Ещё вопрос в админке лиги ВТб постоянно выскакивает окно, оно для чего и может его убрать? | H40: =IFERROR(__xludf.DUMMYFUNCTION("""COMPUTED_VALUE"""),"13:00-14:00") -> 13:00-14:00
...

Sheet Февраль 26
A1: Дата | B1: Ответственный | C1: Клиент | D1: Статус обращения | E1: Срок решения и комментарий | F1: Решение (ссылка на тикет/ссылка на документацию) | G1: Обращение клиента | H1: Время | I1: Статус внесения обращения в Obsidian | J1: Ссылка на Merge Request
A2: 46054 | B2: Мишина Анна | H2: 9:00-10:00
B3: Мишина Анна | C3: Restream | D3: Завершен | E3: Саша сказал надо смотреть upd 05.02: всё должно работать нормально, клиенту отписались | G3: Добрый день, @restream_webcaster, подскажите, не идёт сигнал в Ютуб, вк и рутуб. Все настроено, как надо, но не работает | H3: 10:00-11:00 | I3: Не требует инструкции
B4: Мишина Анна | H4: 11:00-12:00
B5: Мишина Анна | H5: 12:00-13:00
B6: Мишина Анна | H6: 13:00-14:00
B7: Мишина Анна | H7: 14:00-15:00
B8: Мишина Анна | H8: 15:00-16:00
B9: Мишина Анна | H9: 16:00-17:00
B10: Мишина Анна | H10: 17:00-18:00
B11: Мишина Анна | C11: Restream | D11: В работе | E11: аналогично | G11: Добрый день подскажите пожалуйста, что-то второй день не могу запустить рестримы, начинают идти и через минут две пропадают, в чем может быть проблема? | H11: 18:00-19:00
B12: Мишина Анна | H12: 19:00-20:00
B13: Мишина Анна | H13: 20:00-21:00
B14: Мишина Анна | H14: 21:00-22:00
B15: Мишина Анна | H15: 22:00-23:00
A16: 46055 | B16: Мишина Анна | H16: 9:00-10:00
B17: Мишина Анна | H17: 10:00-11:00
B18: Мишина Анна | H18: 11:00-12:00
B19: Мишина Анна | C19: Restream | D19: Завершен | E19: вчерашний, в работе upd 05.02: всё должно работать нормально, клиенту отписались | G19: Добрый день, надеюсь о моём вопросе ещё не забыли? | H19: 12:00-13:00
B20: Мишина Анна | H20: 13:00-14:00
B21: Мишина Анна | H21: 14:00-15:00
B22: Мишина Анна | H22: 15:00-16:00
B23: Мишина Анна | H23: 16:00-17:00
B24: Мишина Анна | H24: 17:00-18:00
B25: Мишина Анна | C25: МатчТВ | D25: Завершен | G25: Добрый вечер! У пользователя на ПК при попытке просмотра на сайте Матч ТВ возникает ошибка "Не удалось установить соединение с сайтом". Проблема возникает в Яндекс Браузере и Гугл Хром. Использует Wi-fi. При использовании другого источника интернета (LTE) проблем нет. IP-адрес 5.44.172.54 | H25: 18:00-19:00 | I25: Добавлена
B26: Мишина Анна | C26: КХЛ | D26: Завершен | E26: редактор доразметил | G26: Подскажите, почему разметка в лисах закончилась на счете 1:2? | H26: 19:00-20:00 | I26: Не требует инструкции
B27: Мишина Анна | C27: МатчТВ | D27: Завершен | E27: там уже 15 примеров | G27: Пользователю из Луганска недоступен просмотр Матч ТВ на сайте. Ошибка "трансляция недоступна в вашем регионе". Date: Mon, 02 Feb 26 20:32:12 +0300 GeoIP country: RU GeoIP country nginx: RU GeoIP region nginx: 00 HTTP_USER_AGENT: Mozilla/5.0 (Windows NT 10.0; Win64; x64) AppleWebKit/537.36 (KHTML, like Gecko) Chrome/142.0.0.0 YaBrowser/25.12.0.0 Safari/537.36 REMOTE_ADDR: 178.158.14.4 HTTP_X_FORWARDED_FOR: 178.158.14.4, 178.158.14.4 IP-Z: 178.158.14.4 Proxied IP: 178.158.14.4 Network Family: common Current UID/SU: / HAS FLASH: false MSE: true ВПН - нет | H27: 20:00-21:00 | I27: Не требует инструкции
B28: Мишина Анна | H28: 21:00-22:00
B29: Мишина Анна | H29: 22:00-23:00
A30: 46056 | B30: Мишина Анна | C30: Restream | D30: Завершен | G30: стрим падает каждые 30 секунд через рестрим, битрейт в ОБС стабильный в чём может быть дело? Такое бывало и на бесплатном тарифе, но сейчас я взял R5, данная проблема появляется также | H30: 9:00-10:00 | I30: Добавлена
B31: Мишина Анна | H31: 10:00-11:00
B32: Мишина Анна | H32: 11:00-12:00
B33: Мишина Анна | H33: 12:00-13:00
B34: Мишина Анна | H34: 13:00-14:00
B35: Мишина Анна | C35: Restream | D35: Завершен | G35: Подскажите, пожалуйста, а надо обложку для эфира публиковать общую у вас или на каждой площадке (вк,ок, ютуб, рутьюб) и можно ли везде делать запланированные эфиры на этих площадках? | H35: 14:00-15:00 | I35: Добавлена
B36: Мишина Анна | H36: 15:00-16:00
B37: Мишина Анна | H37: 16:00-17:00
B38: Мишина Анна | H38: 17:00-18:00
B39: Мишина Анна | H39: 18:00-19:00
B40: Мишина Анна | H40: 19:00-20:00
...

Sheet Декабрь 25
B1: Ответственный | C1: Клиент | D1: Статус обращения | E1: Срок решения и комментарий | F1: Решение (ссылка на тикет/ссылка на документацию) | G1: Обращение клиента | H1: Время | I1: Конышев | J1: Макогонюк | K1: Удалов | L1: Шавло | M1: Соловьёв | N1: Червякова | O1: Толкачев | P1: Макаров | Q1: Курасов
A2: 45992 | B2: Гришина Светлана | C2: МОНИКИ | D2: Завершен | G2: Доброе утро. Не могу подключиться вебинару. | H2: 9:00-10:00 | R2: =COUNTBLANK(B:B) -> 1048141
B3: Гришина Светлана | C3: МОНИКИ | D3: Завершен | E3: Сообщения в чате и обозначение голосом о необходимости включить микрофон не помогли. Присоединилась их администратор и завершила вебинар. | G3: Кафедра Детских болезней. ПК Актуальные вопросы педиатрии. Семинар по ФРМ и физиотерапии. (01.12.25) - https://wbnr.su:50443/rooms?meet=9c39637a-80a2-4a49-8da2-6c84dfaab8df - Здравствуйте! Звука нет | H3: 10:00-11:00
B4: Гришина Светлана | H4: 11:00-12:00
B5: Гришина Светлана | H5: 12:00-13:00
B6: Гришина Светлана | H6: 13:00-14:00
B7: Гришина Светлана | C7: Restream | D7: Завершен | G7: Подскажите, а если мы оплатим тариф Студии - в нее будет входить стандартный траиф рестриминга? | H7: 14:00-15:00
B8: Гришина Светлана | C8: КХЛ | D8: Завершен | E8: Ошибка в саммари в моб. приложении | G8: добрый день поправьте, пожалуйста | H8: 15:00-16:00
B9: Гришина Светлана | H9: 16:00-17:00
B10: Гришина Светлана | H10: 17:00-18:00
B11: Гришина Светлана | H11: 18:00-19:00
B12: Гришина Светлана | H12: 19:00-20:00
B13: Андреева Варвара | C13: КХЛ | D13: Завершен | G13: коллеги, поправьте, пожалуйста, он И.О. Рише (Трактор), Андриевский (Амур), Козлов (Динамо М), Люзенков (Сибирь) - все и.о. | H13: 20:00-21:00
B14: Андреева Варвара | C14: Restream | D14: Завершен | G14: Сейчас запустил трансляцию, толку ноль. Ни на одну площадку контент не приходит. | H14: 21:00-22:00
B15: Андреева Варвара | C15: МатчТВ | D15: Завершен | F15: https://rdm.inventos.ru/issues/165919 | G15: Добрый вечер! У пользователя в приложении на двух устройствах Смарт ТВ LG c2 (OLED65C22LB), приставка dune Pro Vision 4K при просмотре передачи от 30.11.2025 "После футбола с Георгием Черданцевым" наблюдалась проблема: не выводится многоканальный звук (при выборе многоканальной дорожки). Со слов пользователя в программе "После футбола с Георгием Черданцевым" под значком микрофона выбор стерео/многоканал. телевизор подключен по arc к ресиверу. При просмотре на тв для любой аудиодорожки на входе ресивера сигнал стерео. Если включить эту же трансляцию на приставке, то при переключении дорожки на входе ресивера видно переключение 2.0/5.1. При этом, во всех установленных у меня на тв онлайн кинотеатрах, при просмотре контента имеющего 5,1 дорожку вывод на ресивер происходит соответственно в 5,1 по тому же arc каналу. IP 95.25.174.144 | H15: 22:00-23:00
A16: 45993 | B16: Червякова Ольга | H16: 9:00-10:00
B17: Червякова Ольга | H17: 10:00-11:00
B18: Червякова Ольга | H18: 11:00-12:00
B19: Червякова Ольга | C19: Restream | D19: Завершен | G19: Привет, подскажите, как ваша программа работает для стримов на инстаграм и ютуб? Работает ли она если ведущий и тех часть ведут стрим не в России, а с территории ЛатАм или США или ЕС? | H19: 12:00-13:00
B20: Червякова Ольга | C20: ТВСтарт | D20: Завершен | F20: https://rdm.inventos.ru/issues/165935 | G20: Добрый день! Возникла задача, необходимо канал tvstart_4_srt_22904 сделать в режиме listener, с 06.12 по 19.12. Оставим его под одно соревнование. | H20: 13:00-14:00
B21: Червякова Ольга | C21: МХЛ | D21: Завершен | E21: инструкция уже есть | G21: Коллеги, добрый день! Перезалейте, пожалуйста, матч от 01.12 Академия СКА — МХК Динамо СПБ на вебкастер https://disk.yandex.ru/i/ZG2B5WiqZ3ahIQ | H21: 14:00-15:00
B22: Червякова Ольга | C22: КХЛ | D22: Завершен | E22: передаем в чат редакторов | G22: Коллеги, посмотрите, пожалуйста, Гол попал в категорию опасных моментов | H22: 15:00-16:00
B23: Червякова Ольга | H23: 16:00-17:00
B24: Червякова Ольга | H24: 17:00-18:00
B25: Андреева Варвара | H25: 18:00-19:00
B26: Андреева Варвара | H26: 19:00-20:00
B27: Андреева Варвара | H27: 20:00-21:00
B28: Андреева Варвара | H28: 21:00-22:00
B29: Андреева Варвара | H29: 22:00-23:00
A30: 45994 | B30: Червякова Ольга | H30: 9:00-10:00
B31: Червякова Ольга | H31: 10:00-11:00
B32: Червякова Ольга | C32: RDS | D32: Завершен | G32: Всем добрый день! ➡️ В этот уик-энд, 6-7 декабря, у всех трансляций планируем 1 аудиодорожку, только РУС язык. ➡️ Следующий гоночный этап, 24-25 января, у всех трансляций также планируем 1 аудиодорожку, только РУС язык. | H32: 11:00-12:00
B33: Червякова Ольга | H33: 12:00-13:00
B34: Мишина Анна | C34: МОНИКИ | D34: Завершен | G34: Кафедра Поликлинической терапии. ПК Оказание паллиативной медицинской помощи средним медицинским персоналом. Уход за паллиативными пациентами. (03.12.2025) - https://wbnr.su:50443/rooms?meet=491d6288-3067-40c9-9069-8f22fb569a8a - Отсутствуют участники | H34: 13:00-14:00
B35: Мишина Анна | H35: 14:00-15:00
B36: Мишина Анна | C36: МОНИКИ | D36: Завершен | G36: Кафедра Поликлинической терапии. ПК Оказание паллиативной медицинской помощи средним медицинским персоналом. Управление стрессом, релаксационные методики. (03.12.2025) - https://wbnr.su:50443/rooms?meet=40351ee2-1671-44aa-bd9a-b73d60a6e994 - Отсутствуют участники | H36: 15:00-16:00
B37: Мишина Анна | H37: 16:00-17:00
B38: Мишина Анна | H38: 17:00-18:00
B39: Мишина Анна | C39: МХЛ | D39: Завершен | F39: добавлено | G39: почему статус загрузки на нуле продолжительное время | H39: 18:00-19:00
B40: Мишина Анна | H40: 19:00-20:00
...

Sheet Ноябрь 25 
B1: Ответственный | C1: Клиент | D1: Статус обращения | E1: Срок решения и комментарий | F1: Решение (ссылка на тикет/ссылка на документацию) | G1: Обращение клиента | H1: Время | I1: Конышев | J1: Макогонюк | K1: Удалов | L1: Шавло | M1: Соловьёв | N1: Червякова | O1: Толкачев | P1: Макаров | Q1: Курасов
A2: 45962 | B2: Червякова Ольга | H2: 9:00-10:00 | R2: =COUNTBLANK(B:B) -> 1048155
B3: Червякова Ольга | C3: МОНИКИ | G3: Добрый день! Не могу подключиться к вебинару,проблема та же что и вчера. Помогите пожалуйста | H3: 10:00-11:00
B4: Червякова Ольга | H4: 11:00-12:00
B5: Червякова Ольга | H5: 12:00-13:00
B6: Червякова Ольга | H6: 13:00-14:00
B7: Червякова Ольга | H7: 14:00-15:00
B8: Червякова Ольга | H8: 15:00-16:00
B9: Червякова Ольга | H9: 16:00-17:00
B10: Мишина Анна | C10: Restream | D10: Завершен | E10: относится к обращению от 31.10 на почту | G10: Добрый день. А когда будет ответ по моим вопросам? | H10: 17:00-18:00
B11: Мишина Анна | H11: 18:00-19:00
B12: Гришина Светлана | H12: 19:00-20:00
B13: Гришина Светлана | H13: 20:00-21:00
B14: Гришина Светлана | C14: Новый клиент | D14: Завершен | G14: Здравствуйте, не могу разобраться. У вас в API сервера написано, что для формирования подписи нужно добавить "secret – выданный при регистрации Клиента секретный ключ". Вопрос: где его найти? | H14: 21:00-22:00
B15: Гришина Светлана | H15: 22:00-23:00
A16: 45963 | B16: Червякова Ольга | H16: 9:00-10:00
B17: Червякова Ольга | H17: 10:00-11:00
B18: Червякова Ольга | H18: 11:00-12:00
B19: Червякова Ольга | C19: МатчТВ | D19: В работе | E19: относится к обращению от 31.10.2025 | G19: Добрый день! Вернулся пользователь. С его слов при смене качества на более низкое, проблема сохраняется. | H19: 12:00-13:00
B20: Червякова Ольга | C20: Restream | D20: Завершен | G20: Добрый день! У нас перестал работать сервис | H20: 13:00-14:00
B21: Червякова Ольга | C21: МатчТВ | D21: Создан тикет | G21: У пользователя UID EhjbpFfosJs9AbZpN5Wp6R в приложении на Смарт ТВ при просмотре трансляций в 4К подвисание. Наблюдается на всех трансляциях которые были в 4К. Смарт ТВ Samsung QE50QN90AAUXRU подключен по кабелю. Ip адрес 31.133.234.163 | H21: 14:00-15:00
B22: Червякова Ольга | C22: МатчТВ | D22: Завершен | G22: А можно узнать точное время пропадания и появления сигнала ? | H22: 15:00-16:00
B23: Червякова Ольга | C23: МатчТВ | D23: Завершен | G23: На видеоплатформе все настроено верно. @Inventos_tech_sup с сигналом нет проблемы ? | H23: 16:00-17:00
B24: Червякова Ольга | H24: 17:00-18:00
B25: Червякова Ольга | H25: 18:00-19:00
B26: Мишина Анна | H26: 19:00-20:00
B27: Мишина Анна | H27: 20:00-21:00
B28: Мишина Анна | C28: Restream | D28: Завершен | E28: относится к обращению от 31.10 на почту | G28: Добрый вечер! Я запустил тестовый эфир | H28: 21:00-22:00
B29: Мишина Анна | C29: Restream | D29: Завершен | E29: время обращения 23:36. отвалился диск, Саша перекинул пользователя на другой сервер, всё в порядке | G29: Ребят Стрим сваливается! | H29: 22:00-23:00
A30: 45964 | B30: Гришина Светлана | H30: 9:00-10:00
B31: Гришина Светлана | H31: 10:00-11:00
B32: Гришина Светлана | H32: 11:00-12:00
B33: Червякова Ольга | H33: 12:00-13:00
B34: Червякова Ольга | H34: 13:00-14:00
B35: Червякова Ольга | H35: 14:00-15:00
B36: Червякова Ольга | H36: 15:00-16:00
B37: Червякова Ольга | H37: 16:00-17:00
B38: Червякова Ольга | H38: 17:00-18:00
B39: Мишина Анна | H39: 18:00-19:00
B40: Мишина Анна | C40: Restream | D40: Завершен | G40: Я только запустил уже пропусски | H40: 19:00-20:00
...

Sheet Октябрь 25
A1: С | B1: Ответственный | C1: Клиент | D1: Статус обращения | E1: Срок решения и комментарий | F1: Решение (ссылка на тикет/ссылка на документацию) | G1: Обращение клиента | H1: Время | I1: Конышев | J1: Макогонюк | K1: Удалов | L1: Шавло | M1: Соловьёв | N1: Червякова | O1: Толкачев | P1: Макаров | Q1: Курасов
A2: 45931 | B2: Гришина Светлана | H2: 9:00-10:00
B3: Гришина Светлана | H3: 10:00-11:00
B4: Гришина Светлана | C4: Restream | D4: Завершен | G4: Добрый день! Не удается привязать каналы. Нет кнопок, которые указаны в инструкции | H4: 11:00-12:00
B5: Червякова Ольга | C5: Restream | D5: Завершен | G5: Приложение в плей маркете есть? | H5: 12:00-13:00
B6: Червякова Ольга | C6: МатчТВ | D6: Завершен | G6: это канал «Матч ТВ» на Андроид ТВ. Куда делось качество при выборе 50 фпс | H6: 13:00-14:00
B7: Червякова Ольга | C7: МХЛ | D7: Завершен | E7: относится к обращению, внесенному ранее | G7: Колелги, об этой проблеме я писал еще в июле, ничего не поменялось | H7: 14:00-15:00
B8: Червякова Ольга | C8: Restream | D8: Завершен | G8: Почему у вас нет системы поощрения? я на протяжении 5-ти лет пользуюсь вашим сервисом и даю хороший фидбек по технической работе и сбоям... и как-то грустно становится, что даже не можете убрать обязательную плашку с "транслируется через Рестрим.су", которая приписывается в названии. | H8: 15:00-16:00
B9: Червякова Ольга | C9: Restream | D9: Завершен | G9: Доброй ночи. Столкнулся с такой проблемой, что когда выставляю в настройках название своих стримов, то на ютубе на предыдущем видео меняется название... не понимаю как так происходит, но это напрягает | H9: 16:00-17:00
B10: Червякова Ольга | C10: Restream | D10: Завершен | G10: Добрый день, подскажите пж как настроить интеграцию с youtube? | H10: 17:00-18:00
B11: Червякова Ольга | C11: Новый клиент | D11: Завершен | E11: обратился не от клиента | G11: Мне нужно установить приложение на смарт ТВ | H11: 18:00-19:00
B12: Кузнецова Алиса | H12: 19:00-20:00
B13: Кузнецова Алиса | H13: 20:00-21:00
B14: Червякова Ольга | H14: 21:00-22:00
B15: Червякова Ольга | H15: 22:00-23:00
A16: 45932 | B16: Толкачев Егор | H16: 9:00-10:00
B17: Толкачев Егор | H17: 10:00-11:00
B18: Толкачев Егор | H18: 11:00-12:00
B19: Червякова Ольга | C19: Restream | D19: Завершен | E19: обращение за 01.10 | G19: Все-таки возник еще один вопрос: При привязке ютуб, не могу выбрать канал, который администрирую. Только только личный аккаунт. | H19: 12:00-13:00
B20: Червякова Ольга | H20: 13:00-14:00
B21: Червякова Ольга | C21: Restream | D21: Завершен | G21: Снова прерывания стримов начались, у меня отдача идёт... а стримы пишет завершены | H21: 14:00-15:00
B22: Червякова Ольга | H22: 15:00-16:00
B23: Червякова Ольга | H23: 16:00-17:00
B24: Червякова Ольга | C24: Restream | D24: Завершен | G24: добры день. не могу понять, как вывести трансляцию на собственный сайт? где взять хтмл код? | H24: 17:00-18:00
B25: Белов Дмитрий | H25: 18:00-19:00
B26: Белов Дмитрий | H26: 19:00-20:00
B27: Белов Дмитрий | H27: 20:00-21:00
B28: Белов Дмитрий | H28: 21:00-22:00
B29: Белов Дмитрий | H29: 22:00-23:00
A30: 45933 | B30: Белов Дмитрий | C30: Restream | G30: срыв происходит спустя 3-4 минуты, максимум 4 минуты 57-58 секунд и трансляция прерывается... это случалось и днём и в ночное время | H30: 9:00-10:00
B31: Белов Дмитрий | C31: ЛигаВТБ | D31: Завершен | G31: Здравствуйте. Скажите, почему нет видео текущего сезона лиги ВТБ? Спасибо | H31: 10:00-11:00
B32: Белов Дмитрий | H32: 11:00-12:00
B33: Червякова Ольга | C33: ЛигаВТБ | D33: Завершен | G33: Здравствуйте. Скажите, почему нет видео текущего сезона лиги ВТБ? Спасибо | H33: 12:00-13:00
B34: Червякова Ольга | C34: Restream | D34: Завершен | G34: срыв происходит спустя 3-4 минуты, максимум 4 минуты 57-58 секунд и трансляция прерывается... это случалось и днём и в ночное время | H34: 13:00-14:00
B35: Червякова Ольга | H35: 14:00-15:00
B36: Червякова Ольга | H36: 15:00-16:00
B37: Червякова Ольга | H37: 16:00-17:00
B38: Червякова Ольга | H38: 17:00-18:00
B39: Червякова Ольга | H39: 18:00-19:00
B40: Червякова Ольга | H40: 19:00-20:00
...

Sheet Сентябрь 25
B1: Ответственный | C1: Клиент | D1: Статус обращения | E1: Срок решения и комментарий | F1: Решение (ссылка на тикет/ссылка на документацию) | G1: Обращение клиента | H1: Время | I1: Конышев | J1: Макогонюк | K1: Удалов | L1: Шавло | M1: Соловьёв | N1: Червякова | O1: Толкачев | P1: Макаров | Q1: Курасов
A2: 45901 | B2: Червякова Ольга | H2: 9:00-10:00
B3: Червякова Ольга | H3: 10:00-11:00
B4: Червякова Ольга | H4: 11:00-12:00
B5: Червякова Ольга | H5: 12:00-13:00
B6: Червякова Ольга | H6: 13:00-14:00
B7: Червякова Ольга | H7: 14:00-15:00
B8: Червякова Ольга | H8: 15:00-16:00
B9: Червякова Ольга | H9: 16:00-17:00
B10: Червякова Ольга | H10: 17:00-18:00
B11: Щемелинин Владислав | H11: 18:00-19:00
B12: Щемелинин Владислав | H12: 19:00-20:00
B13: Щемелинин Владислав | H13: 20:00-21:00
B14: Щемелинин Владислав | H14: 21:00-22:00
B15: Щемелинин Владислав | H15: 22:00-23:00
A16: 45902 | B16: Червякова Ольга | H16: 9:00-10:00
B17: Червякова Ольга | H17: 10:00-11:00
B18: Червякова Ольга | H18: 11:00-12:00
B19: Червякова Ольга | H19: 12:00-13:00
B20: Червякова Ольга | H20: 13:00-14:00
B21: Червякова Ольга | H21: 14:00-15:00
B22: Червякова Ольга | H22: 15:00-16:00
B23: Червякова Ольга | H23: 16:00-17:00
B24: Червякова Ольга | H24: 17:00-18:00
B25: Гришина Светлана | H25: 18:00-19:00
B26: Гришина Светлана | H26: 19:00-20:00
B27: Гришина Светлана | H27: 20:00-21:00
B28: Гришина Светлана | H28: 21:00-22:00
B29: Гришина Светлана | H29: 22:00-23:00
A30: 45903 | B30: Щемелинин Владислав | H30: 9:00-10:00
B31: Щемелинин Владислав | H31: 10:00-11:00
B32: Щемелинин Владислав | H32: 11:00-12:00
B33: Щемелинин Владислав | H33: 12:00-13:00
B34: Червякова Ольга | H34: 13:00-14:00
B35: Червякова Ольга | C35: Ifree | D35: Завершен | G35: Добрый день! Не могли бы вы пожалуйста обрезать загруженно видео с 01:37:46 и до конца | H35: 14:00-15:00
B36: Червякова Ольга | H36: 15:00-16:00
B37: Червякова Ольга | H37: 16:00-17:00
B38: Червякова Ольга | H38: 17:00-18:00
B39: Толкачев Егор | H39: 18:00-19:00
B40: Толкачев Егор | H40: 19:00-20:00
...

